/home/robotlabx/anaconda3/envs/pytorchenv/lib/python3.7/site-packages/torch/nn/functional.py:718: UserWarning: Named tensors and all their associated APIs are an experimental feature and subject to change. Please do not use them for anything important until they are released as stable. (Triggered internally at  /pytorch/c10/core/TensorImpl.h:1156.)
  return torch.max_pool2d(input, kernel_size, stride, padding, dilation, ceil_mode)
 Average loss:  34528000.0  --- Iterations:  1  --- Epochs:  1
 Average loss:  29436686.0  --- Iterations:  2  --- Epochs:  1
 Average loss:  22584360.0  --- Iterations:  3  --- Epochs:  1
 Average loss:  18327690.0  --- Iterations:  4  --- Epochs:  1
 Average loss:  15667925.0  --- Iterations:  5  --- Epochs:  1
 Average loss:  13818411.0  --- Iterations:  6  --- Epochs:  1
 Average loss:  12215455.0  --- Iterations:  7  --- Epochs:  1
 Average loss:  10941914.0  --- Iterations:  8  --- Epochs:  1
 Average loss:  10035595.0  --- Iterations:  9  --- Epochs:  1
 Average loss:  9184603.0  --- Iterations:  10  --- Epochs:  1
Starting evaluation
Traceback (most recent call last):
  File "enet_sanity.py", line 449, in <module>
    depth_loss = depth_criterion(pred, pcl.to(device))
  File "/home/robotlabx/anaconda3/envs/pytorchenv/lib/python3.7/site-packages/torch/nn/modules/module.py", line 1051, in _call_impl
    return forward_call(*input, **kwargs)
  File "/home/robotlabx/Desktop/DTAI/decnet2022/src/models/criteria.py", line 17, in forward
    diff = target - pred
RuntimeError: Expected all tensors to be on the same device, but found at least two devices, cuda:0 and cpu!