2022-01-28 08:52:15,850 INFO    MainThread:4104 [internal.py:wandb_internal():90] W&B internal server running at pid: 4104, started at: 2022-01-28 08:52:15.850580
2022-01-28 08:52:15,852 DEBUG   HandlerThread:4104 [handler.py:handle_request():130] handle_request: check_version
2022-01-28 08:52:15,852 INFO    WriterThread:4104 [datastore.py:open_for_write():77] open: /home/robotlabx/Desktop/DTAI/decnet2022/src/models/wandb/run-20220128_085215-121v72hl/run-121v72hl.wandb
2022-01-28 08:52:15,853 DEBUG   SenderThread:4104 [sender.py:send():234] send: header
2022-01-28 08:52:15,853 DEBUG   SenderThread:4104 [sender.py:send_request():248] send_request: check_version
2022-01-28 08:52:20,854 DEBUG   SenderThread:4104 [sender.py:send():234] send: run
2022-01-28 08:52:50,459 DEBUG   HandlerThread:4104 [handler.py:handle_request():130] handle_request: shutdown
2022-01-28 08:52:50,459 INFO    HandlerThread:4104 [handler.py:finish():731] shutting down handler
2022-01-28 08:52:50,468 INFO    WriterThread:4104 [datastore.py:close():281] close: /home/robotlabx/Desktop/DTAI/decnet2022/src/models/wandb/run-20220128_085215-121v72hl/run-121v72hl.wandb
2022-01-28 08:52:54,493 ERROR   SenderThread:4104 [retry.py:__call__():126] Retry attempt failed:
Traceback (most recent call last):
  File "/home/robotlabx/.local/lib/python3.7/site-packages/urllib3/connection.py", line 175, in _new_conn
    (self._dns_host, self.port), self.timeout, **extra_kw
  File "/home/robotlabx/.local/lib/python3.7/site-packages/urllib3/util/connection.py", line 95, in create_connection
    raise err
  File "/home/robotlabx/.local/lib/python3.7/site-packages/urllib3/util/connection.py", line 85, in create_connection
    sock.connect(sa)
socket.timeout: timed out

During handling of the above exception, another exception occurred:

Traceback (most recent call last):
  File "/home/robotlabx/.local/lib/python3.7/site-packages/urllib3/connectionpool.py", line 710, in urlopen
    chunked=chunked,
  File "/home/robotlabx/.local/lib/python3.7/site-packages/urllib3/connectionpool.py", line 386, in _make_request
    self._validate_conn(conn)
  File "/home/robotlabx/.local/lib/python3.7/site-packages/urllib3/connectionpool.py", line 1040, in _validate_conn
    conn.connect()
  File "/home/robotlabx/.local/lib/python3.7/site-packages/urllib3/connection.py", line 358, in connect
    conn = self._new_conn()
  File "/home/robotlabx/.local/lib/python3.7/site-packages/urllib3/connection.py", line 182, in _new_conn
    % (self.host, self.timeout),
urllib3.exceptions.ConnectTimeoutError: (<urllib3.connection.HTTPSConnection object at 0x7ff4bcf9bd30>, 'Connection to api.wandb.ai timed out. (connect timeout=10)')

During handling of the above exception, another exception occurred:

Traceback (most recent call last):
  File "/home/robotlabx/.local/lib/python3.7/site-packages/requests/adapters.py", line 449, in send
    timeout=timeout
  File "/home/robotlabx/.local/lib/python3.7/site-packages/urllib3/connectionpool.py", line 786, in urlopen
    method, url, error=e, _pool=self, _stacktrace=sys.exc_info()[2]
  File "/home/robotlabx/.local/lib/python3.7/site-packages/urllib3/util/retry.py", line 592, in increment
    raise MaxRetryError(_pool, url, error or ResponseError(cause))
urllib3.exceptions.MaxRetryError: HTTPSConnectionPool(host='api.wandb.ai', port=443): Max retries exceeded with url: /graphql (Caused by ConnectTimeoutError(<urllib3.connection.HTTPSConnection object at 0x7ff4bcf9bd30>, 'Connection to api.wandb.ai timed out. (connect timeout=10)'))

During handling of the above exception, another exception occurred:

Traceback (most recent call last):
  File "/home/robotlabx/anaconda3/envs/pytorchenv/lib/python3.7/site-packages/wandb/sdk/lib/retry.py", line 102, in __call__
    result = self._call_fn(*args, **kwargs)
  File "/home/robotlabx/anaconda3/envs/pytorchenv/lib/python3.7/site-packages/wandb/sdk/internal/internal_api.py", line 141, in execute
    return self.client.execute(*args, **kwargs)
  File "/home/robotlabx/anaconda3/envs/pytorchenv/lib/python3.7/site-packages/wandb/vendor/gql-0.2.0/gql/client.py", line 52, in execute
    result = self._get_result(document, *args, **kwargs)
  File "/home/robotlabx/anaconda3/envs/pytorchenv/lib/python3.7/site-packages/wandb/vendor/gql-0.2.0/gql/client.py", line 60, in _get_result
    return self.transport.execute(document, *args, **kwargs)
  File "/home/robotlabx/anaconda3/envs/pytorchenv/lib/python3.7/site-packages/wandb/vendor/gql-0.2.0/gql/transport/requests.py", line 38, in execute
    request = requests.post(self.url, **post_args)
  File "/home/robotlabx/.local/lib/python3.7/site-packages/requests/api.py", line 119, in post
    return request('post', url, data=data, json=json, **kwargs)
  File "/home/robotlabx/.local/lib/python3.7/site-packages/requests/api.py", line 61, in request
    return session.request(method=method, url=url, **kwargs)
  File "/home/robotlabx/.local/lib/python3.7/site-packages/requests/sessions.py", line 542, in request
    resp = self.send(prep, **send_kwargs)
  File "/home/robotlabx/.local/lib/python3.7/site-packages/requests/sessions.py", line 655, in send
    r = adapter.send(request, **kwargs)
  File "/home/robotlabx/.local/lib/python3.7/site-packages/requests/adapters.py", line 504, in send
    raise ConnectTimeout(e, request=request)
requests.exceptions.ConnectTimeout: HTTPSConnectionPool(host='api.wandb.ai', port=443): Max retries exceeded with url: /graphql (Caused by ConnectTimeoutError(<urllib3.connection.HTTPSConnection object at 0x7ff4bcf9bd30>, 'Connection to api.wandb.ai timed out. (connect timeout=10)'))
2022-01-28 08:53:36,228 INFO    MainThread:4104 [internal.py:handle_exit():77] Internal process exited
