2022-01-28 08:52:15,369 INFO    MainThread:4040 [wandb_setup.py:_flush():71] setting env: {}
2022-01-28 08:52:15,369 INFO    MainThread:4040 [wandb_setup.py:_flush():71] setting login settings: {}
2022-01-28 08:52:15,370 INFO    MainThread:4040 [wandb_init.py:_log_setup():371] Logging user logs to /home/robotlabx/Desktop/DTAI/decnet2022/src/models/wandb/run-20220128_085215-121v72hl/logs/debug.log
2022-01-28 08:52:15,370 INFO    MainThread:4040 [wandb_init.py:_log_setup():372] Logging internal logs to /home/robotlabx/Desktop/DTAI/decnet2022/src/models/wandb/run-20220128_085215-121v72hl/logs/debug-internal.log
2022-01-28 08:52:15,370 INFO    MainThread:4040 [wandb_init.py:init():404] calling init triggers
2022-01-28 08:52:15,370 INFO    MainThread:4040 [wandb_init.py:init():411] wandb.init called with sweep_config: {}
config: {}
2022-01-28 08:52:15,370 INFO    MainThread:4040 [wandb_init.py:init():460] starting backend
2022-01-28 08:52:15,370 INFO    MainThread:4040 [backend.py:_multiprocessing_setup():101] multiprocessing start_methods=fork,spawn,forkserver, using: spawn
2022-01-28 08:52:15,395 INFO    MainThread:4040 [backend.py:ensure_launched():216] starting backend process...
2022-01-28 08:52:15,412 INFO    MainThread:4040 [backend.py:ensure_launched():222] started backend process with pid: 4104
2022-01-28 08:52:15,412 INFO    MainThread:4040 [wandb_init.py:init():469] backend started and connected
2022-01-28 08:52:15,415 INFO    MainThread:4040 [wandb_init.py:init():533] updated telemetry
2022-01-28 08:52:15,454 INFO    MainThread:4040 [wandb_init.py:init():563] communicating current version
2022-01-28 08:52:20,455 INFO    MainThread:4040 [wandb_init.py:init():578] communicating run to backend with 30 second timeout
2022-01-28 08:52:43,739 ERROR   Thread-1  :4040 [retry.py:__call__():126] Retry attempt failed:
Traceback (most recent call last):
  File "/home/robotlabx/.local/lib/python3.7/site-packages/urllib3/connection.py", line 175, in _new_conn
    (self._dns_host, self.port), self.timeout, **extra_kw
  File "/home/robotlabx/.local/lib/python3.7/site-packages/urllib3/util/connection.py", line 95, in create_connection
    raise err
  File "/home/robotlabx/.local/lib/python3.7/site-packages/urllib3/util/connection.py", line 85, in create_connection
    sock.connect(sa)
socket.timeout: timed out

During handling of the above exception, another exception occurred:

Traceback (most recent call last):
  File "/home/robotlabx/.local/lib/python3.7/site-packages/urllib3/connectionpool.py", line 710, in urlopen
    chunked=chunked,
  File "/home/robotlabx/.local/lib/python3.7/site-packages/urllib3/connectionpool.py", line 386, in _make_request
    self._validate_conn(conn)
  File "/home/robotlabx/.local/lib/python3.7/site-packages/urllib3/connectionpool.py", line 1040, in _validate_conn
    conn.connect()
  File "/home/robotlabx/.local/lib/python3.7/site-packages/urllib3/connection.py", line 358, in connect
    conn = self._new_conn()
  File "/home/robotlabx/.local/lib/python3.7/site-packages/urllib3/connection.py", line 182, in _new_conn
    % (self.host, self.timeout),
urllib3.exceptions.ConnectTimeoutError: (<urllib3.connection.HTTPSConnection object at 0x7fe6b43aee80>, 'Connection to api.wandb.ai timed out. (connect timeout=10)')

During handling of the above exception, another exception occurred:

Traceback (most recent call last):
  File "/home/robotlabx/.local/lib/python3.7/site-packages/requests/adapters.py", line 449, in send
    timeout=timeout
  File "/home/robotlabx/.local/lib/python3.7/site-packages/urllib3/connectionpool.py", line 786, in urlopen
    method, url, error=e, _pool=self, _stacktrace=sys.exc_info()[2]
  File "/home/robotlabx/.local/lib/python3.7/site-packages/urllib3/util/retry.py", line 592, in increment
    raise MaxRetryError(_pool, url, error or ResponseError(cause))
urllib3.exceptions.MaxRetryError: HTTPSConnectionPool(host='api.wandb.ai', port=443): Max retries exceeded with url: /graphql (Caused by ConnectTimeoutError(<urllib3.connection.HTTPSConnection object at 0x7fe6b43aee80>, 'Connection to api.wandb.ai timed out. (connect timeout=10)'))

During handling of the above exception, another exception occurred:

Traceback (most recent call last):
  File "/home/robotlabx/anaconda3/envs/pytorchenv/lib/python3.7/site-packages/wandb/sdk/lib/retry.py", line 102, in __call__
    result = self._call_fn(*args, **kwargs)
  File "/home/robotlabx/anaconda3/envs/pytorchenv/lib/python3.7/site-packages/wandb/sdk/internal/internal_api.py", line 141, in execute
    return self.client.execute(*args, **kwargs)
  File "/home/robotlabx/anaconda3/envs/pytorchenv/lib/python3.7/site-packages/wandb/vendor/gql-0.2.0/gql/client.py", line 52, in execute
    result = self._get_result(document, *args, **kwargs)
  File "/home/robotlabx/anaconda3/envs/pytorchenv/lib/python3.7/site-packages/wandb/vendor/gql-0.2.0/gql/client.py", line 60, in _get_result
    return self.transport.execute(document, *args, **kwargs)
  File "/home/robotlabx/anaconda3/envs/pytorchenv/lib/python3.7/site-packages/wandb/vendor/gql-0.2.0/gql/transport/requests.py", line 38, in execute
    request = requests.post(self.url, **post_args)
  File "/home/robotlabx/.local/lib/python3.7/site-packages/requests/api.py", line 119, in post
    return request('post', url, data=data, json=json, **kwargs)
  File "/home/robotlabx/.local/lib/python3.7/site-packages/requests/api.py", line 61, in request
    return session.request(method=method, url=url, **kwargs)
  File "/home/robotlabx/.local/lib/python3.7/site-packages/requests/sessions.py", line 542, in request
    resp = self.send(prep, **send_kwargs)
  File "/home/robotlabx/.local/lib/python3.7/site-packages/requests/sessions.py", line 655, in send
    r = adapter.send(request, **kwargs)
  File "/home/robotlabx/.local/lib/python3.7/site-packages/requests/adapters.py", line 504, in send
    raise ConnectTimeout(e, request=request)
requests.exceptions.ConnectTimeout: HTTPSConnectionPool(host='api.wandb.ai', port=443): Max retries exceeded with url: /graphql (Caused by ConnectTimeoutError(<urllib3.connection.HTTPSConnection object at 0x7fe6b43aee80>, 'Connection to api.wandb.ai timed out. (connect timeout=10)'))
2022-01-28 08:52:50,457 INFO    MainThread:4040 [interface_shared.py:_communicate_run():313] couldn't get run from backend
2022-01-28 08:52:50,457 ERROR   MainThread:4040 [wandb_init.py:init():583] backend process timed out
2022-01-28 08:52:50,457 ERROR   MainThread:4040 [wandb_init.py:init():592] encountered error: Error communicating with wandb process
try: wandb.init(settings=wandb.Settings(start_method='fork'))
or:  wandb.init(settings=wandb.Settings(start_method='thread'))
For more info see: https://docs.wandb.ai/library/init#init-start-error
2022-01-28 08:53:36,069 WARNING MainThread:4040 [wandb_init.py:init():952] interrupted
Traceback (most recent call last):
  File "/home/robotlabx/anaconda3/envs/pytorchenv/lib/python3.7/site-packages/wandb/sdk/wandb_init.py", line 931, in init
    run = wi.init()
  File "/home/robotlabx/anaconda3/envs/pytorchenv/lib/python3.7/site-packages/wandb/sdk/wandb_init.py", line 596, in init
    backend.cleanup()
  File "/home/robotlabx/anaconda3/envs/pytorchenv/lib/python3.7/site-packages/wandb/sdk/backend/backend.py", line 247, in cleanup
    self.wandb_process.join()
  File "/home/robotlabx/anaconda3/envs/pytorchenv/lib/python3.7/multiprocessing/process.py", line 140, in join
    res = self._popen.wait(timeout)
  File "/home/robotlabx/anaconda3/envs/pytorchenv/lib/python3.7/multiprocessing/popen_fork.py", line 48, in wait
    return self.poll(os.WNOHANG if timeout == 0.0 else 0)
  File "/home/robotlabx/anaconda3/envs/pytorchenv/lib/python3.7/multiprocessing/popen_fork.py", line 28, in poll
    pid, sts = os.waitpid(self.pid, flag)
KeyboardInterrupt
